<?xml version='1.0' encoding='utf-8'?>
<mujoco model="panda">
  <compiler angle="radian" meshdir="assets" autolimits="true" />

  <option integrator="implicit" />
  <option gravity="0 0 -9.81" />

  <default>
    <default class="panda">
      <material specular="0.5" shininess="0.25" />
      <joint armature="0.1" damping="1" axis="0 0 1" range="-2.8973 2.8973" />
      <general dyntype="none" biastype="none" ctrlrange="-87 87" forcerange="-87 87" />
      <default class="finger">
        <joint axis="0 1 0" type="slide" range="0 0.04" />
      </default>

      <default class="visual">
        <geom type="mesh" contype="0" conaffinity="0" group="2" />
      </default>
      <default class="collision">
        <geom type="mesh" group="3" />
        <default class="fingertip_pad_collision_1">
          <geom type="box" size="0.0085 0.004 0.0085" pos="0 0.0055 0.0445" />
        </default>
        <default class="fingertip_pad_collision_2">
          <geom type="box" size="0.003 0.002 0.003" pos="0.0055 0.002 0.05" />
        </default>
        <default class="fingertip_pad_collision_3">
          <geom type="box" size="0.003 0.002 0.003" pos="-0.0055 0.002 0.05" />
        </default>
        <default class="fingertip_pad_collision_4">
          <geom type="box" size="0.003 0.002 0.0035" pos="0.0055 0.002 0.0395" />
        </default>
        <default class="fingertip_pad_collision_5">
          <geom type="box" size="0.003 0.002 0.0035" pos="-0.0055 0.002 0.0395" />
        </default>
      </default>
    </default>
  </default>

  <asset>
    <material class="panda" name="white" rgba="1 1 1 1" />
    <material class="panda" name="off_white" rgba="0.901961 0.921569 0.929412 1" />
    <material class="panda" name="black" rgba="0.25 0.25 0.25 1" />
    <material class="panda" name="green" rgba="0 1 0 1" />
    <material class="panda" name="light_blue" rgba="0.039216 0.541176 0.780392 1" />

    
    <mesh name="link0_c" file="link0.stl" />
    <mesh name="link1_c" file="link1.stl" />
    <mesh name="link2_c" file="link2.stl" />
    <mesh name="link3_c" file="link3.stl" />
    <mesh name="link4_c" file="link4.stl" />
    <mesh name="link5_c0" file="link5_collision_0.obj" />
    <mesh name="link5_c1" file="link5_collision_1.obj" />
    <mesh name="link5_c2" file="link5_collision_2.obj" />
    <mesh name="link6_c" file="link6.stl" />
    <mesh name="link7_c" file="link7.stl" />
    <mesh name="hand_c" file="hand.stl" />

    
    <mesh file="link0_0.obj" />
    <mesh file="link0_1.obj" />
    <mesh file="link0_2.obj" />
    <mesh file="link0_3.obj" />
    <mesh file="link0_4.obj" />
    <mesh file="link0_5.obj" />
    <mesh file="link0_7.obj" />
    <mesh file="link0_8.obj" />
    <mesh file="link0_9.obj" />
    <mesh file="link0_10.obj" />
    <mesh file="link0_11.obj" />
    <mesh file="link1.obj" />
    <mesh file="link2.obj" />
    <mesh file="link3_0.obj" />
    <mesh file="link3_1.obj" />
    <mesh file="link3_2.obj" />
    <mesh file="link3_3.obj" />
    <mesh file="link4_0.obj" />
    <mesh file="link4_1.obj" />
    <mesh file="link4_2.obj" />
    <mesh file="link4_3.obj" />
    <mesh file="link5_0.obj" />
    <mesh file="link5_1.obj" />
    <mesh file="link5_2.obj" />
    <mesh file="link6_0.obj" />
    <mesh file="link6_1.obj" />
    <mesh file="link6_2.obj" />
    <mesh file="link6_3.obj" />
    <mesh file="link6_4.obj" />
    <mesh file="link6_5.obj" />
    <mesh file="link6_6.obj" />
    <mesh file="link6_7.obj" />
    <mesh file="link6_8.obj" />
    <mesh file="link6_9.obj" />
    <mesh file="link6_10.obj" />
    <mesh file="link6_11.obj" />
    <mesh file="link6_12.obj" />
    <mesh file="link6_13.obj" />
    <mesh file="link6_14.obj" />
    <mesh file="link6_15.obj" />
    <mesh file="link6_16.obj" />
    <mesh file="link7_0.obj" />
    <mesh file="link7_1.obj" />
    <mesh file="link7_2.obj" />
    <mesh file="link7_3.obj" />
    <mesh file="link7_4.obj" />
    <mesh file="link7_5.obj" />
    <mesh file="link7_6.obj" />
    <mesh file="link7_7.obj" />
    <mesh file="hand_0.obj" />
    <mesh file="hand_1.obj" />
    <mesh file="hand_2.obj" />
    <mesh file="hand_3.obj" />
    <mesh file="hand_4.obj" />
    <mesh file="finger_0.obj" />
    <mesh file="finger_1.obj" />
  <mesh name="chess_king_mesh" file="chess_king.stl" scale="0.001 0.001 0.001" /></asset>

  <worldbody>
    <light name="top" pos="0 0 2" mode="trackcom" />
    <body name="link0" childclass="panda">
      <inertial mass="0.629769" pos="-0.041018 -0.00014 0.049974" fullinertia="0.00315 0.00388 0.004285 8.2904e-7 0.00015 8.2299e-6" />
      <geom mesh="link0_0" material="off_white" class="visual" />
      <geom mesh="link0_1" material="black" class="visual" />
      <geom mesh="link0_2" material="off_white" class="visual" />
      <geom mesh="link0_3" material="black" class="visual" />
      <geom mesh="link0_4" material="off_white" class="visual" />
      <geom mesh="link0_5" material="black" class="visual" />
      <geom mesh="link0_7" material="white" class="visual" />
      <geom mesh="link0_8" material="white" class="visual" />
      <geom mesh="link0_9" material="black" class="visual" />
      <geom mesh="link0_10" material="off_white" class="visual" />
      <geom mesh="link0_11" material="white" class="visual" />
      <geom mesh="link0_c" class="collision" />
      <body name="link1" pos="0 0 0.333">
        <inertial mass="4.970684" pos="0.003875 0.002081 -0.04762" fullinertia="0.70337 0.70661 0.0091170 -0.00013900 0.0067720 0.019169" />
        <joint name="joint1" />
        <geom material="white" mesh="link1" class="visual" />
        <geom mesh="link1_c" class="collision" />
        <body name="link2" quat="1 -1 0 0">
          <inertial mass="0.646926" pos="-0.003141 -0.02872 0.003495" fullinertia="0.0079620 2.8110e-2 2.5995e-2 -3.925e-3 1.0254e-2 7.04e-4" />
          <joint name="joint2" range="-1.7628 1.7628" />
          <geom material="white" mesh="link2" class="visual" />
          <geom mesh="link2_c" class="collision" />
          <body name="link3" pos="0 -0.316 0" quat="1 1 0 0">
            <joint name="joint3" />
            <inertial mass="3.228604" pos="2.7518e-2 3.9252e-2 -6.6502e-2" fullinertia="3.7242e-2 3.6155e-2 1.083e-2 -4.761e-3 -1.1396e-2 -1.2805e-2" />
            <geom mesh="link3_0" material="white" class="visual" />
            <geom mesh="link3_1" material="white" class="visual" />
            <geom mesh="link3_2" material="white" class="visual" />
            <geom mesh="link3_3" material="black" class="visual" />
            <geom mesh="link3_c" class="collision" />
            <body name="link4" pos="0.0825 0 0" quat="1 1 0 0">
              <inertial mass="3.587895" pos="-5.317e-2 1.04419e-1 2.7454e-2" fullinertia="2.5853e-2 1.9552e-2 2.8323e-2 7.796e-3 -1.332e-3 8.641e-3" />
              <joint name="joint4" range="-3.0718 -0.0698" />
              <geom mesh="link4_0" material="white" class="visual" />
              <geom mesh="link4_1" material="white" class="visual" />
              <geom mesh="link4_2" material="black" class="visual" />
              <geom mesh="link4_3" material="white" class="visual" />
              <geom mesh="link4_c" class="collision" />
              <body name="link5" pos="-0.0825 0.384 0" quat="1 -1 0 0">
                <inertial mass="1.225946" pos="-1.1953e-2 4.1065e-2 -3.8437e-2" fullinertia="3.5549e-2 2.9474e-2 8.627e-3 -2.117e-3 -4.037e-3 2.29e-4" />
                <joint name="joint5" />
                <geom mesh="link5_0" material="black" class="visual" />
                <geom mesh="link5_1" material="white" class="visual" />
                <geom mesh="link5_2" material="white" class="visual" />
                <geom mesh="link5_c0" class="collision" />
                <geom mesh="link5_c1" class="collision" />
                <geom mesh="link5_c2" class="collision" />
                <body name="link6" quat="1 1 0 0">
                  <inertial mass="1.666555" pos="6.0149e-2 -1.4117e-2 -1.0517e-2" fullinertia="1.964e-3 4.354e-3 5.433e-3 1.09e-4 -1.158e-3 3.41e-4" />
                  <joint name="joint6" range="-0.0175 3.7525" />
                  <geom mesh="link6_0" material="off_white" class="visual" />
                  <geom mesh="link6_1" material="white" class="visual" />
                  <geom mesh="link6_2" material="black" class="visual" />
                  <geom mesh="link6_3" material="white" class="visual" />
                  <geom mesh="link6_4" material="white" class="visual" />
                  <geom mesh="link6_5" material="white" class="visual" />
                  <geom mesh="link6_6" material="white" class="visual" />
                  <geom mesh="link6_7" material="light_blue" class="visual" />
                  <geom mesh="link6_8" material="light_blue" class="visual" />
                  <geom mesh="link6_9" material="black" class="visual" />
                  <geom mesh="link6_10" material="black" class="visual" />
                  <geom mesh="link6_11" material="white" class="visual" />
                  <geom mesh="link6_12" material="green" class="visual" />
                  <geom mesh="link6_13" material="white" class="visual" />
                  <geom mesh="link6_14" material="black" class="visual" />
                  <geom mesh="link6_15" material="black" class="visual" />
                  <geom mesh="link6_16" material="white" class="visual" />
                  <geom mesh="link6_c" class="collision" />
                  <body name="link7" pos="0.088 0 0" quat="1 1 0 0">
                    <inertial mass="7.35522e-01" pos="1.0517e-2 -4.252e-3 6.1597e-2" fullinertia="1.2516e-2 1.0027e-2 4.815e-3 -4.28e-4 -1.196e-3 -7.41e-4" />
                    <joint name="joint7" />
                    <geom mesh="link7_0" material="white" class="visual" />
                    <geom mesh="link7_1" material="black" class="visual" />
                    <geom mesh="link7_2" material="black" class="visual" />
                    <geom mesh="link7_3" material="black" class="visual" />
                    <geom mesh="link7_4" material="black" class="visual" />
                    <geom mesh="link7_5" material="black" class="visual" />
                    <geom mesh="link7_6" material="black" class="visual" />
                    <geom mesh="link7_7" material="white" class="visual" />
                    <geom mesh="link7_c" class="collision" />
                    <body name="hand" pos="0 0 0.107" quat="0.9238795 0 0 -0.3826834">
                      <inertial mass="0.73" pos="-0.01 0 0.03" diaginertia="0.001 0.0025 0.0017" />
                      <geom mesh="hand_0" material="off_white" class="visual" />
                      <geom mesh="hand_1" material="black" class="visual" />
                      <geom mesh="hand_2" material="black" class="visual" />
                      <geom mesh="hand_3" material="white" class="visual" />
                      <geom mesh="hand_4" material="off_white" class="visual" />
                      <geom mesh="hand_c" class="collision" />
                      <body name="left_finger" pos="0 0 0.0584">
                        <inertial mass="0.015" pos="0 0 0" diaginertia="2.375e-6 2.375e-6 7.5e-7" />
                        <joint name="finger_joint1" class="finger" />
                        <geom mesh="finger_0" material="off_white" class="visual" />
                        <geom mesh="finger_1" material="black" class="visual" />
                        <geom mesh="finger_0" class="collision" />
                        <geom class="fingertip_pad_collision_1" />
                        <geom class="fingertip_pad_collision_2" />
                        <geom class="fingertip_pad_collision_3" />
                        <geom class="fingertip_pad_collision_4" />
                        <geom class="fingertip_pad_collision_5" />
                      </body>
                      <body name="right_finger" pos="0 0 0.0584" quat="0 0 0 1">
                        <inertial mass="0.015" pos="0 0 0" diaginertia="2.375e-6 2.375e-6 7.5e-7" />
                        <joint name="finger_joint2" class="finger" />
                        <geom mesh="finger_0" material="off_white" class="visual" />
                        <geom mesh="finger_1" material="black" class="visual" />
                        <geom mesh="finger_0" class="collision" />
                        <geom class="fingertip_pad_collision_1" />
                        <geom class="fingertip_pad_collision_2" />
                        <geom class="fingertip_pad_collision_3" />
                        <geom class="fingertip_pad_collision_4" />
                        <geom class="fingertip_pad_collision_5" />
                      </body>
                    </body>
                  </body>
                </body>
              </body>
            </body>
          </body>
        </body>
      </body>
    </body>
    <geom name="ground" type="plane" size="3 3 0.1" rgba="0.8 0.9 1 1" />
    
    
  <geom name="table_0" type="box" size="0.15 0.15 0.15" pos="0.45 0.0 0.15" rgba="0.4 0.3 0.2 1" friction="1.5 0.5 0.1" contype="1" conaffinity="1" /><body name="ChessPiece_0" pos="0.3947241375913748 -0.0005065586830256929 0.302" quat="0.9997627967815235 0.0 0.0 0.021779581529177784"><freejoint name="chess_piece_joint_0" /><geom name="chess_piece_visual_0" type="mesh" mesh="chess_king_mesh" rgba="0.85 0.75 0.55 1" contype="0" conaffinity="0" mass="0" /><geom name="chess_piece_base_col_0" type="box" size="0.016 0.016 0.016" pos="0.016 0.016 0.016" rgba="0.85 0.75 0.55 0.3" density="500" friction="1.5 1.5 0.5" contype="1" conaffinity="1" condim="4" /><geom name="chess_piece_stem_col_0" type="cylinder" size="0.010 0.030" pos="0.016 0.016 0.060" rgba="0.85 0.75 0.55 0.2" density="500" friction="1.5 0.5 0.1" contype="1" conaffinity="1" condim="4" /></body><geom name="marker_finger_left" type="sphere" size="0.008" pos="0.4082702238669908 0.0561370953886876 0.35975316111611827" rgba="0 1 0 0.9" contype="0" conaffinity="0" /><geom name="marker_finger_right" type="sphere" size="0.008" pos="0.4117541303228672 -0.023787008583810602 0.35975316111611827" rgba="0 1 0 0.9" contype="0" conaffinity="0" /><geom name="marker_grasp_center" type="sphere" size="0.010" pos="0.410012177094929 0.0161750434024385 0.35975316111611827" rgba="1 1 0 0.9" contype="0" conaffinity="0" /><geom name="marker_pre_grasp" type="sphere" size="0.010" pos="0.410012177094929 0.0161750434024385 0.4597531611161183" rgba="0 1 1 0.9" contype="0" conaffinity="0" /><geom name="marker_lift" type="sphere" size="0.010" pos="0.410012177094929 0.0161750434024385 0.5097531611161182" rgba="1 0 1 0.9" contype="0" conaffinity="0" /><geom name="marker_descent_1" type="sphere" size="0.004" pos="0.410012177094929 0.0161750434024385 0.4472531611161183" rgba="0.3 0.3 1 0.7" contype="0" conaffinity="0" /><geom name="marker_descent_2" type="sphere" size="0.004" pos="0.410012177094929 0.0161750434024385 0.4347531611161183" rgba="0.3 0.3 1 0.7" contype="0" conaffinity="0" /><geom name="marker_descent_3" type="sphere" size="0.004" pos="0.410012177094929 0.0161750434024385 0.42225316111611827" rgba="0.3 0.3 1 0.7" contype="0" conaffinity="0" /><geom name="marker_descent_4" type="sphere" size="0.004" pos="0.410012177094929 0.0161750434024385 0.40975316111611826" rgba="0.3 0.3 1 0.7" contype="0" conaffinity="0" /><geom name="marker_descent_5" type="sphere" size="0.004" pos="0.410012177094929 0.0161750434024385 0.3972531611161183" rgba="0.3 0.3 1 0.7" contype="0" conaffinity="0" /><geom name="marker_descent_6" type="sphere" size="0.004" pos="0.410012177094929 0.0161750434024385 0.3847531611161183" rgba="0.3 0.3 1 0.7" contype="0" conaffinity="0" /><geom name="marker_descent_7" type="sphere" size="0.004" pos="0.410012177094929 0.0161750434024385 0.3722531611161183" rgba="0.3 0.3 1 0.7" contype="0" conaffinity="0" /><geom name="marker_ascent_1" type="sphere" size="0.004" pos="0.410012177094929 0.0161750434024385 0.38475316111611824" rgba="1 0 1 0.5" contype="0" conaffinity="0" /><geom name="marker_ascent_2" type="sphere" size="0.004" pos="0.410012177094929 0.0161750434024385 0.40975316111611826" rgba="1 0 1 0.5" contype="0" conaffinity="0" /><geom name="marker_ascent_3" type="sphere" size="0.004" pos="0.410012177094929 0.0161750434024385 0.4347531611161183" rgba="1 0 1 0.5" contype="0" conaffinity="0" /><geom name="marker_ascent_4" type="sphere" size="0.004" pos="0.410012177094929 0.0161750434024385 0.45975316111611825" rgba="1 0 1 0.5" contype="0" conaffinity="0" /><geom name="marker_ascent_5" type="sphere" size="0.004" pos="0.410012177094929 0.0161750434024385 0.4847531611161182" rgba="1 0 1 0.5" contype="0" conaffinity="0" /><geom name="marker_faxis_l_1" type="sphere" size="0.003" pos="0.40966378644934137 0.02416745379968832 0.35975316111611827" rgba="0 0.7 0 0.5" contype="0" conaffinity="0" /><geom name="marker_faxis_r_1" type="sphere" size="0.003" pos="0.4103605677405166 0.00818263300518868 0.35975316111611827" rgba="0 0.7 0 0.5" contype="0" conaffinity="0" /><geom name="marker_faxis_l_2" type="sphere" size="0.003" pos="0.4093153958037537 0.03215986419693814 0.35975316111611827" rgba="0 0.7 0 0.5" contype="0" conaffinity="0" /><geom name="marker_faxis_r_2" type="sphere" size="0.003" pos="0.4107089583861043 0.00019022260793885928 0.35975316111611827" rgba="0 0.7 0 0.5" contype="0" conaffinity="0" /><geom name="marker_faxis_l_3" type="sphere" size="0.003" pos="0.4089670051581661 0.040152274594187964 0.35975316111611827" rgba="0 0.7 0 0.5" contype="0" conaffinity="0" /><geom name="marker_faxis_r_3" type="sphere" size="0.003" pos="0.4110573490316919 -0.0078021877893109624 0.35975316111611827" rgba="0 0.7 0 0.5" contype="0" conaffinity="0" /><geom name="marker_faxis_l_4" type="sphere" size="0.003" pos="0.4086186145125784 0.04814468499143778 0.35975316111611827" rgba="0 0.7 0 0.5" contype="0" conaffinity="0" /><geom name="marker_faxis_r_4" type="sphere" size="0.003" pos="0.41140573967727956 -0.01579459818656078 0.35975316111611827" rgba="0 0.7 0 0.5" contype="0" conaffinity="0" /><geom name="marker_drop_target" type="cylinder" size="0.025 0.001" pos="0.4927947319074651 -0.007426314311507056 0.301" rgba="1 0.2 0.2 0.8" contype="0" conaffinity="0" /><geom name="marker_pre_place" type="sphere" size="0.010" pos="0.4927947319074651 -0.007426314311507056 0.49999999999999994" rgba="1 0.5 0 0.9" contype="0" conaffinity="0" /><geom name="marker_place" type="sphere" size="0.010" pos="0.4927947319074651 -0.007426314311507056 0.36" rgba="1 0 0 0.9" contype="0" conaffinity="0" /><geom name="marker_retreat" type="sphere" size="0.010" pos="0.4927947319074651 -0.007426314311507056 0.52" rgba="1 1 1 0.9" contype="0" conaffinity="0" /><geom name="marker_transfer_1" type="sphere" size="0.004" pos="0.420359996446496 0.013224873688195304 0.5085340159766034" rgba="1 0.6 0.8 0.5" contype="0" conaffinity="0" /><geom name="marker_transfer_2" type="sphere" size="0.004" pos="0.430707815798063 0.01027470397395211 0.5073148708370887" rgba="1 0.6 0.8 0.5" contype="0" conaffinity="0" /><geom name="marker_transfer_3" type="sphere" size="0.004" pos="0.44105563514963003 0.007324534259708916 0.5060957256975739" rgba="1 0.6 0.8 0.5" contype="0" conaffinity="0" /><geom name="marker_transfer_4" type="sphere" size="0.004" pos="0.451403454501197 0.004374364545465722 0.5048765805580591" rgba="1 0.6 0.8 0.5" contype="0" conaffinity="0" /><geom name="marker_transfer_5" type="sphere" size="0.004" pos="0.46175127385276404 0.0014241948312225267 0.5036574354185444" rgba="1 0.6 0.8 0.5" contype="0" conaffinity="0" /><geom name="marker_transfer_6" type="sphere" size="0.004" pos="0.4720990932043311 -0.0015259748830206664 0.5024382902790295" rgba="1 0.6 0.8 0.5" contype="0" conaffinity="0" /><geom name="marker_transfer_7" type="sphere" size="0.004" pos="0.4824469125558981 -0.004476144597263861 0.5012191451395147" rgba="1 0.6 0.8 0.5" contype="0" conaffinity="0" /><geom name="marker_place_desc_1" type="sphere" size="0.004" pos="0.4927947319074651 -0.007426314311507056 0.4766666666666666" rgba="1 0.5 0 0.5" contype="0" conaffinity="0" /><geom name="marker_place_desc_2" type="sphere" size="0.004" pos="0.4927947319074651 -0.007426314311507056 0.4533333333333333" rgba="1 0.5 0 0.5" contype="0" conaffinity="0" /><geom name="marker_place_desc_3" type="sphere" size="0.004" pos="0.4927947319074651 -0.007426314311507056 0.42999999999999994" rgba="1 0.5 0 0.5" contype="0" conaffinity="0" /><geom name="marker_place_desc_4" type="sphere" size="0.004" pos="0.4927947319074651 -0.007426314311507056 0.4066666666666666" rgba="1 0.5 0 0.5" contype="0" conaffinity="0" /><geom name="marker_place_desc_5" type="sphere" size="0.004" pos="0.4927947319074651 -0.007426314311507056 0.3833333333333333" rgba="1 0.5 0 0.5" contype="0" conaffinity="0" /><geom name="marker_gz_0" type="sphere" size="0.002" pos="0.410012177094929 0.0161750434024385 0.3797531611161183" rgba="0.5 0.5 0.5 0.6" contype="0" conaffinity="0" /><geom name="marker_gz_1" type="sphere" size="0.002" pos="0.410012177094929 0.0161750434024385 0.3697531611161183" rgba="0.5 0.5 0.5 0.6" contype="0" conaffinity="0" /><geom name="marker_gz_2" type="sphere" size="0.002" pos="0.410012177094929 0.0161750434024385 0.35975316111611827" rgba="0.5 0.5 0.5 0.6" contype="0" conaffinity="0" /><geom name="marker_gz_3" type="sphere" size="0.002" pos="0.410012177094929 0.0161750434024385 0.34975316111611826" rgba="0.5 0.5 0.5 0.6" contype="0" conaffinity="0" /><geom name="marker_gz_4" type="sphere" size="0.002" pos="0.410012177094929 0.0161750434024385 0.33975316111611825" rgba="0.5 0.5 0.5 0.6" contype="0" conaffinity="0" /></worldbody>

  <tendon>
    <fixed name="split">
      <joint joint="finger_joint1" coef="0.5" />
      <joint joint="finger_joint2" coef="0.5" />
    </fixed>
  </tendon>

  <equality>
    <joint joint1="finger_joint1" joint2="finger_joint2" solimp="0.95 0.99 0.001" solref="0.005 1" />
  </equality>

  <actuator>
    <general class="panda" name="actuator1" joint="joint1" gainprm="1" />
    <general class="panda" name="actuator2" joint="joint2" gainprm="1" />
    <general class="panda" name="actuator3" joint="joint3" gainprm="1" />
    <general class="panda" name="actuator4" joint="joint4" gainprm="1" />
    <general class="panda" name="actuator5" joint="joint5" gainprm="1" ctrlrange="-12 12" forcerange="-12 12" />
    <general class="panda" name="actuator6" joint="joint6" gainprm="1" forcerange="-12 12" ctrlrange="-12 12" />
    <general class="panda" name="actuator7" joint="joint7" gainprm="1" ctrlrange="-12 12" forcerange="-12 12" />
    <position name="actuator8" tendon="split" ctrlrange="0.005 0.04" kp="400" />
  </actuator>

  
</mujoco>